Workbook

Sheet Mode d'emploi
A1: ATELIER COCOTTE LEAN | « Le Contrat Cadencé » | Classeur de calcul des KPI
B3: Pôle Formation UIMM CVDL, S. Jaubert, version 2.0
B5: CODE COULEUR
C6: Cellule à saisir pendant l'atelier
C7: Cellule calculée, ne pas modifier
C8: Paramètre du contrat, à figer avant la journée
B10: ORDRE DES OPÉRATIONS
B11: Étape 1 | C11: Avant la journée : vérifier l'onglet Paramètres. Le contrat et le temps de cycle de référence y sont figés.
B12: Étape 2 | C12: Pendant chaque round : le Client remplit le registre d'expédition papier, le Chronométreur relève les temps de cycle.
B13: Étape 3 | C13: Après chaque round : reporter le registre dans l'onglet du round. Les indicateurs se calculent seuls.
B14: Étape 4 | C14: En fin de journée : ouvrir l'onglet Synthèse, projeter les tableaux et les graphiques.
B15: Étape 5 | C15: Le test de la loi de Little se lit directement dans la Synthèse. C'est le temps fort du débriefing.
B17: SAISIE DES HEURES
C18: Le chronomètre projeté affiche mm:ss depuis le top départ.
C19: On saisit les minutes et les secondes dans deux colonnes distinctes, en nombres entiers.
C20: Exemple : une pièce sortie à 07:25 se saisit 7 dans la colonne min et 25 dans la colonne s.
B22: POINT DE VIGILANCE
C23: Une ligne du registre n'est complète que si l'heure de sortie est renseignée.
C24: Les pièces restées dans l'atelier au signal STOP ne sont pas des sorties : elles sont du WIP.
C25: Le WIP se compte zone par zone, physiquement, il ne se déduit pas du registre.
B27: REMISE À ZÉRO AVANT LA SÉANCE
C28: Les trois onglets de round contiennent un jeu de démonstration issu d'une simulation.
C29: Il permet de vérifier le classeur et de projeter les graphiques avant la journée.
C30: Pour repartir à vide : dans chaque onglet de round, sélectionner et effacer toutes les cellules jaunes.
C31: Plages concernées : C6:G9, C14:C18, E23:E26, C28, puis K5:P49.
C33: Les chiffres de démonstration ne sont pas des relevés terrain. Ce sont des résultats de simulation
C34: à variabilité opératoire, produits pour caler le scénario. Ne pas les annoncer comme des références.

Sheet Paramètres
A1: PARAMÈTRES DU CONTRAT ET DE LA LIGNE
B3: Paramètre | C3: Valeur | D3: Commentaire
B4: Durée d'une vacation (minutes) | C4: 16 | D4: Temps d'ouverture du round
B5: Durée d'une vacation (secondes) | C5: =C4*60 -> 960 | D5: Calculé
B6: Demande client par vacation (pièces) | C6: 24 | D6: Clause du contrat
B7: Nombre d'enlèvements | C7: 4 | D7: Un camion toutes les 4 minutes
B8: Quantité par enlèvement (pièces) | C8: =C6/C7 -> 6 | D8: Calculé
B9: Takt Time (s/pièce) | C9: =C5/C6 -> 40 | D9: Temps disponible divisé par la demande
B10: Nombre de postes | C10: 4 | D10: P1 à P4
B11: Temps de cycle de référence (s) | C11: 35 | D11: Goulot mesuré au round 1. Figé pour les 3 rounds.
B13: POURQUOI FIGER LE TEMPS DE CYCLE DE RÉFÉRENCE
B14: Le TRG rapporte la production à une cadence de référence.
B15: Si l'on met à jour cette référence après chaque chantier Kaizen, le TRG s'améliore mécaniquement
B16: et ne mesure plus rien de comparable d'un round à l'autre.
B17: On retient donc le temps de cycle du poste goulot mesuré au round 1, et on le garde identique.

Sheet Round 1
A1: ROUND 1 | saisie des relevés
A2: JEU DE DÉMONSTRATION ISSU D'UNE SIMULATION. Effacer toutes les cellules jaunes avant la séance.
B3: 1. TEMPS DE CYCLE PAR POSTE (secondes) | K3: 4. REGISTRE D'EXPÉDITION
B4: Poste | C4: C1 | D4: C2 | E4: C3 | F4: C4 | G4: C5 | H4: Médiane | I4: Écart au takt | K4: Jeton | L4: Entrée (min) | M4: Entrée (s) | N4: Sortie (min) | O4: Sortie (s) | P4: Conforme O/N | Q4: Lead Time (s)
B5: P1 | C5: 24 | D5: 26 | E5: 25 | F5: 27 | G5: 25 | H5: =IF(COUNT(C5:G5)=0,"",MEDIAN(C5:G5)) -> 25 | I5: =IF(H5="","",H5-Paramètres!$C$9) -> -15 | K5: 1 | L5: 0 | M5: 0 | N5: 8 | O5: 51 | P5: N | Q5: =IF(OR(N5="",K5=""),"",(N5*60+O5)-(L5*60+M5)) -> 531
B6: P2 | C6: 29 | D6: 31 | E6: 30 | F6: 32 | G6: 30 | H6: =IF(COUNT(C6:G6)=0,"",MEDIAN(C6:G6)) -> 30 | I6: =IF(H6="","",H6-Paramètres!$C$9) -> -10 | K6: 2 | L6: 0 | M6: 0 | N6: 8 | O6: 51 | P6: O | Q6: =IF(OR(N6="",K6=""),"",(N6*60+O6)-(L6*60+M6)) -> 531
B7: P3 | C7: 34 | D7: 36 | E7: 35 | F7: 37 | G7: 35 | H7: =IF(COUNT(C7:G7)=0,"",MEDIAN(C7:G7)) -> 35 | I7: =IF(H7="","",H7-Paramètres!$C$9) -> -5 | K7: 3 | L7: 0 | M7: 0 | N7: 8 | O7: 51 | P7: O | Q7: =IF(OR(N7="",K7=""),"",(N7*60+O7)-(L7*60+M7)) -> 531
B8: P4 | C8: 24 | D8: 26 | E8: 25 | F8: 26 | G8: 25 | H8: =IF(COUNT(C8:G8)=0,"",MEDIAN(C8:G8)) -> 25 | I8: =IF(H8="","",H8-Paramètres!$C$9) -> -15 | K8: 4 | L8: 0 | M8: 0 | N8: 8 | O8: 51 | P8: O | Q8: =IF(OR(N8="",K8=""),"",(N8*60+O8)-(L8*60+M8)) -> 531
B9: Contenu travail | H9: =IF(COUNT(H5:H8)=0,"",SUM(H5:H8)) -> 115 | K9: 5 | L9: 0 | M9: 0 | N9: 8 | O9: 51 | P9: O | Q9: =IF(OR(N9="",K9=""),"",(N9*60+O9)-(L9*60+M9)) -> 531
B10: Poste goulot (s) | H10: =IF(COUNT(H5:H8)=0,"",MAX(H5:H8)) -> 35 | K10: 6 | L10: 1 | M10: 60 | N10: 12 | O10: 13 | P10: O | Q10: =IF(OR(N10="",K10=""),"",(N10*60+O10)-(L10*60+M10)) -> 613
B11: Écart max entre postes (s) | H11: =IF(COUNT(H5:H8)=0,"",MAX(H5:H8)-MIN(H5:H8)) -> 10 | K11: 7 | L11: 1 | M11: 60 | N11: 12 | O11: 13 | P11: O | Q11: =IF(OR(N11="",K11=""),"",(N11*60+O11)-(L11*60+M11)) -> 613
K12: 8 | L12: 1 | M12: 60 | N12: 12 | O12: 13 | P12: O | Q12: =IF(OR(N12="",K12=""),"",(N12*60+O12)-(L12*60+M12)) -> 613
B13: 2. EN-COURS AU SIGNAL STOP (comptage physique par zone) | K13: 9 | L13: 1 | M13: 60 | N13: 12 | O13: 13 | P13: N | Q13: =IF(OR(N13="",K13=""),"",(N13*60+O13)-(L13*60+M13)) -> 613
B14: Zone | C14: Pièces | K14: 10 | L14: 1 | M14: 60 | N14: 12 | O14: 13 | P14: N | Q14: =IF(OR(N14="",K14=""),"",(N14*60+O14)-(L14*60+M14)) -> 613
B15: Stock matière vers P1 | C15: 2 | K15: 11 | L15: 4 | M15: 16 | N15: 15 | O15: 29 | P15: O | Q15: =IF(OR(N15="",K15=""),"",(N15*60+O15)-(L15*60+M15)) -> 673
B16: P1 vers P2 | C16: 7 | K16: 12 | L16: 4 | M16: 16 | N16: 15 | O16: 29 | P16: O | Q16: =IF(OR(N16="",K16=""),"",(N16*60+O16)-(L16*60+M16)) -> 673
B17: P2 vers P3 | C17: 10 | K17: 13 | L17: 4 | M17: 16 | N17: 15 | O17: 29 | P17: O | Q17: =IF(OR(N17="",K17=""),"",(N17*60+O17)-(L17*60+M17)) -> 673
B18: P3 vers P4 | C18: 5 | K18: 14 | L18: 4 | M18: 16 | N18: 15 | O18: 29 | P18: N | Q18: =IF(OR(N18="",K18=""),"",(N18*60+O18)-(L18*60+M18)) -> 673
B19: P4 vers Client | C19: 2 | K19: 15 | L19: 4 | M19: 16 | N19: 15 | O19: 29 | P19: O | Q19: =IF(OR(N19="",K19=""),"",(N19*60+O19)-(L19*60+M19)) -> 673
B20: WIP TOTAL | C20: =SUM(C15:C19) -> 26 | K20: 16 | L20: 6 | M20: 0 | Q20: =IF(OR(N20="",K20=""),"",(N20*60+O20)-(L20*60+M20))
K21: 17 | L21: 6 | M21: 24 | Q21: =IF(OR(N21="",K21=""),"",(N21*60+O21)-(L21*60+M21))
K22: 18 | L22: 6 | M22: 48 | Q22: =IF(OR(N22="",K22=""),"",(N22*60+O22)-(L22*60+M22))
B23: 3. TABLEAU DE MARCHE | K23: 19 | L23: 7 | M23: 12 | Q23: =IF(OR(N23="",K23=""),"",(N23*60+O23)-(L23*60+M23))
B24: Camion | C24: Heure (min) | D24: Dû | E24: Livré | F24: Retard cumulé | K24: 20 | L24: 7 | M24: 36 | Q24: =IF(OR(N24="",K24=""),"",(N24*60+O24)-(L24*60+M24))
B25: 1 | C25: =(Paramètres!$C$4/Paramètres!$C$7)*1 -> 4 | D25: =Paramètres!$C$8 -> 6 | E25: 0 | F25: =SUM($D$25:D25)-SUM($E$25:E25) -> 6 | K25: 21 | L25: 8 | M25: 0 | Q25: =IF(OR(N25="",K25=""),"",(N25*60+O25)-(L25*60+M25))
B26: 2 | C26: =(Paramètres!$C$4/Paramètres!$C$7)*2 -> 8 | D26: =Paramètres!$C$8 -> 6 | E26: 0 | F26: =SUM($D$25:D26)-SUM($E$25:E26) -> 12 | K26: 22 | L26: 8 | M26: 24 | Q26: =IF(OR(N26="",K26=""),"",(N26*60+O26)-(L26*60+M26))
B27: 3 | C27: =(Paramètres!$C$4/Paramètres!$C$7)*3 -> 12 | D27: =Paramètres!$C$8 -> 6 | E27: 4 | F27: =SUM($D$25:D27)-SUM($E$25:E27) -> 14 | K27: 23 | L27: 8 | M27: 48 | Q27: =IF(OR(N27="",K27=""),"",(N27*60+O27)-(L27*60+M27))
B28: 4 | C28: =(Paramètres!$C$4/Paramètres!$C$7)*4 -> 16 | D28: =Paramètres!$C$8 -> 6 | E28: 7 | F28: =SUM($D$25:D28)-SUM($E$25:E28) -> 13 | K28: 24 | L28: 9 | M28: 12 | Q28: =IF(OR(N28="",K28=""),"",(N28*60+O28)-(L28*60+M28))
B29: Total | D29: =SUM(D25:D28) -> 24 | E29: =SUM(E25:E28) -> 11 | K29: 25 | L29: 9 | M29: 36 | Q29: =IF(OR(N29="",K29=""),"",(N29*60+O29)-(L29*60+M29))
K30: 26 | L30: 10 | M30: 0 | Q30: =IF(OR(N30="",K30=""),"",(N30*60+O30)-(L30*60+M30))
B31: Arrêts de ligne cumulés (s) | C31: 0 | K31: 27 | L31: 10 | M31: 24 | Q31: =IF(OR(N31="",K31=""),"",(N31*60+O31)-(L31*60+M31))
K32: 28 | L32: 10 | M32: 48 | Q32: =IF(OR(N32="",K32=""),"",(N32*60+O32)-(L32*60+M32))
K33: 29 | L33: 11 | M33: 12 | Q33: =IF(OR(N33="",K33=""),"",(N33*60+O33)-(L33*60+M33))
B34: 5. INDICATEURS CALCULÉS | K34: 30 | L34: 11 | M34: 36 | Q34: =IF(OR(N34="",K34=""),"",(N34*60+O34)-(L34*60+M34))
B35: Indicateur | C35: Valeur | D35: Unité | K35: 31 | L35: 12 | M35: 0 | Q35: =IF(OR(N35="",K35=""),"",(N35*60+O35)-(L35*60+M35))
B36: Pièces lancées | C36: =COUNT(K5:K49) -> 40 | D36: pièces | K36: 32 | L36: 12 | M36: 24 | Q36: =IF(OR(N36="",K36=""),"",(N36*60+O36)-(L36*60+M36))
B37: Pièces sorties | C37: =COUNT(Q5:Q49) -> 15 | D37: pièces | K37: 33 | L37: 12 | M37: 48 | Q37: =IF(OR(N37="",K37=""),"",(N37*60+O37)-(L37*60+M37))
B38: Pièces conformes | C38: =COUNTIFS(P5:P49,"O",Q5:Q49,">=0") -> 11 | D38: pièces | K38: 34 | L38: 13 | M38: 12 | Q38: =IF(OR(N38="",K38=""),"",(N38*60+O38)-(L38*60+M38))
B39: Taux de qualité | C39: =IFERROR(C38/C37,"") -> 0.73333333 | K39: 35 | L39: 13 | M39: 36 | Q39: =IF(OR(N39="",K39=""),"",(N39*60+O39)-(L39*60+M39))
B40: WIP (comptage physique) | C40: =C20 -> 26 | D40: pièces | K40: 36 | L40: 14 | M40: 0 | Q40: =IF(OR(N40="",K40=""),"",(N40*60+O40)-(L40*60+M40))
...

Sheet Round 2
A1: ROUND 2 | saisie des relevés
A2: JEU DE DÉMONSTRATION ISSU D'UNE SIMULATION. Effacer toutes les cellules jaunes avant la séance.
B3: 1. TEMPS DE CYCLE PAR POSTE (secondes) | K3: 4. REGISTRE D'EXPÉDITION
B4: Poste | C4: C1 | D4: C2 | E4: C3 | F4: C4 | G4: C5 | H4: Médiane | I4: Écart au takt | K4: Jeton | L4: Entrée (min) | M4: Entrée (s) | N4: Sortie (min) | O4: Sortie (s) | P4: Conforme O/N | Q4: Lead Time (s)
B5: P1 | C5: 24 | D5: 26 | E5: 25 | F5: 27 | G5: 25 | H5: =IF(COUNT(C5:G5)=0,"",MEDIAN(C5:G5)) -> 25 | I5: =IF(H5="","",H5-Paramètres!$C$9) -> -15 | K5: 1 | L5: 0 | M5: 0 | N5: 1 | O5: 54 | P5: O | Q5: =IF(OR(N5="",K5=""),"",(N5*60+O5)-(L5*60+M5)) -> 114
B6: P2 | C6: 29 | D6: 31 | E6: 30 | F6: 32 | G6: 30 | H6: =IF(COUNT(C6:G6)=0,"",MEDIAN(C6:G6)) -> 30 | I6: =IF(H6="","",H6-Paramètres!$C$9) -> -10 | K6: 2 | L6: 0 | M6: 0 | N6: 2 | O6: 38 | P6: O | Q6: =IF(OR(N6="",K6=""),"",(N6*60+O6)-(L6*60+M6)) -> 158
B7: P3 | C7: 34 | D7: 36 | E7: 35 | F7: 37 | G7: 35 | H7: =IF(COUNT(C7:G7)=0,"",MEDIAN(C7:G7)) -> 35 | I7: =IF(H7="","",H7-Paramètres!$C$9) -> -5 | K7: 3 | L7: 0 | M7: 0 | N7: 3 | O7: 14 | P7: N | Q7: =IF(OR(N7="",K7=""),"",(N7*60+O7)-(L7*60+M7)) -> 194
B8: P4 | C8: 24 | D8: 26 | E8: 25 | F8: 26 | G8: 25 | H8: =IF(COUNT(C8:G8)=0,"",MEDIAN(C8:G8)) -> 25 | I8: =IF(H8="","",H8-Paramètres!$C$9) -> -15 | K8: 4 | L8: 0 | M8: 0 | N8: 3 | O8: 53 | P8: N | Q8: =IF(OR(N8="",K8=""),"",(N8*60+O8)-(L8*60+M8)) -> 233
B9: Contenu travail | H9: =IF(COUNT(H5:H8)=0,"",SUM(H5:H8)) -> 115 | K9: 5 | L9: 0 | M9: 0 | N9: 4 | O9: 19 | P9: O | Q9: =IF(OR(N9="",K9=""),"",(N9*60+O9)-(L9*60+M9)) -> 259
B10: Poste goulot (s) | H10: =IF(COUNT(H5:H8)=0,"",MAX(H5:H8)) -> 35 | K10: 6 | L10: 0 | M10: 0 | N10: 4 | O10: 56 | P10: O | Q10: =IF(OR(N10="",K10=""),"",(N10*60+O10)-(L10*60+M10)) -> 296
B11: Écart max entre postes (s) | H11: =IF(COUNT(H5:H8)=0,"",MAX(H5:H8)-MIN(H5:H8)) -> 10 | K11: 7 | L11: 1 | M11: 54 | N11: 5 | O11: 37 | P11: O | Q11: =IF(OR(N11="",K11=""),"",(N11*60+O11)-(L11*60+M11)) -> 223
K12: 8 | L12: 2 | M12: 38 | N12: 5 | O12: 59 | P12: O | Q12: =IF(OR(N12="",K12=""),"",(N12*60+O12)-(L12*60+M12)) -> 201
B13: 2. EN-COURS AU SIGNAL STOP (comptage physique par zone) | K13: 9 | L13: 3 | M13: 14 | N13: 6 | O13: 41 | P13: O | Q13: =IF(OR(N13="",K13=""),"",(N13*60+O13)-(L13*60+M13)) -> 207
B14: Zone | C14: Pièces | K14: 10 | L14: 3 | M14: 53 | N14: 7 | O14: 17 | P14: O | Q14: =IF(OR(N14="",K14=""),"",(N14*60+O14)-(L14*60+M14)) -> 204
B15: Stock matière vers P1 | C15: 0 | K15: 11 | L15: 4 | M15: 19 | N15: 7 | O15: 44 | P15: O | Q15: =IF(OR(N15="",K15=""),"",(N15*60+O15)-(L15*60+M15)) -> 205
B16: P1 vers P2 | C16: 2 | K16: 12 | L16: 4 | M16: 56 | N16: 8 | O16: 13 | P16: O | Q16: =IF(OR(N16="",K16=""),"",(N16*60+O16)-(L16*60+M16)) -> 197
B17: P2 vers P3 | C17: 2 | K17: 13 | L17: 5 | M17: 37 | N17: 8 | O17: 52 | P17: O | Q17: =IF(OR(N17="",K17=""),"",(N17*60+O17)-(L17*60+M17)) -> 195
B18: P3 vers P4 | C18: 1 | K18: 14 | L18: 5 | M18: 59 | N18: 9 | O18: 34 | P18: O | Q18: =IF(OR(N18="",K18=""),"",(N18*60+O18)-(L18*60+M18)) -> 215
B19: P4 vers Client | C19: 1 | K19: 15 | L19: 6 | M19: 41 | N19: 10 | O19: 1 | P19: O | Q19: =IF(OR(N19="",K19=""),"",(N19*60+O19)-(L19*60+M19)) -> 200
B20: WIP TOTAL | C20: =SUM(C15:C19) -> 6 | K20: 16 | L20: 7 | M20: 17 | N20: 10 | O20: 34 | P20: O | Q20: =IF(OR(N20="",K20=""),"",(N20*60+O20)-(L20*60+M20)) -> 197
K21: 17 | L21: 7 | M21: 44 | N21: 11 | O21: 13 | P21: O | Q21: =IF(OR(N21="",K21=""),"",(N21*60+O21)-(L21*60+M21)) -> 209
K22: 18 | L22: 8 | M22: 13 | N22: 12 | O22: 5 | P22: O | Q22: =IF(OR(N22="",K22=""),"",(N22*60+O22)-(L22*60+M22)) -> 232
B23: 3. TABLEAU DE MARCHE | K23: 19 | L23: 8 | M23: 52 | N23: 12 | O23: 37 | P23: O | Q23: =IF(OR(N23="",K23=""),"",(N23*60+O23)-(L23*60+M23)) -> 225
B24: Camion | C24: Heure (min) | D24: Dû | E24: Livré | F24: Retard cumulé | K24: 20 | L24: 9 | M24: 34 | N24: 13 | O24: 21 | P24: O | Q24: =IF(OR(N24="",K24=""),"",(N24*60+O24)-(L24*60+M24)) -> 227
B25: 1 | C25: =(Paramètres!$C$4/Paramètres!$C$7)*1 -> 4 | D25: =Paramètres!$C$8 -> 6 | E25: 2 | F25: =SUM($D$25:D25)-SUM($E$25:E25) -> 4 | K25: 21 | L25: 10 | M25: 1 | N25: 14 | O25: 6 | P25: N | Q25: =IF(OR(N25="",K25=""),"",(N25*60+O25)-(L25*60+M25)) -> 245
B26: 2 | C26: =(Paramètres!$C$4/Paramètres!$C$7)*2 -> 8 | D26: =Paramètres!$C$8 -> 6 | E26: 7 | F26: =SUM($D$25:D26)-SUM($E$25:E26) -> 3 | K26: 22 | L26: 10 | M26: 34 | N26: 14 | O26: 36 | P26: N | Q26: =IF(OR(N26="",K26=""),"",(N26*60+O26)-(L26*60+M26)) -> 242
B27: 3 | C27: =(Paramètres!$C$4/Paramètres!$C$7)*3 -> 12 | D27: =Paramètres!$C$8 -> 6 | E27: 6 | F27: =SUM($D$25:D27)-SUM($E$25:E27) -> 3 | K27: 23 | L27: 11 | M27: 13 | N27: 14 | O27: 59 | P27: O | Q27: =IF(OR(N27="",K27=""),"",(N27*60+O27)-(L27*60+M27)) -> 226
B28: 4 | C28: =(Paramètres!$C$4/Paramètres!$C$7)*4 -> 16 | D28: =Paramètres!$C$8 -> 6 | E28: 5 | F28: =SUM($D$25:D28)-SUM($E$25:E28) -> 4 | K28: 24 | L28: 12 | M28: 5 | N28: 15 | O28: 33 | P28: O | Q28: =IF(OR(N28="",K28=""),"",(N28*60+O28)-(L28*60+M28)) -> 208
B29: Total | D29: =SUM(D25:D28) -> 24 | E29: =SUM(E25:E28) -> 20 | K29: 25 | L29: 12 | M29: 48 | Q29: =IF(OR(N29="",K29=""),"",(N29*60+O29)-(L29*60+M29))
K30: 26 | L30: 13 | M30: 20 | Q30: =IF(OR(N30="",K30=""),"",(N30*60+O30)-(L30*60+M30))
B31: Arrêts de ligne cumulés (s) | C31: 15 | K31: 27 | L31: 13 | M31: 52 | Q31: =IF(OR(N31="",K31=""),"",(N31*60+O31)-(L31*60+M31))
K32: 28 | L32: 14 | M32: 24 | Q32: =IF(OR(N32="",K32=""),"",(N32*60+O32)-(L32*60+M32))
K33: 29 | L33: 14 | M33: 56 | Q33: =IF(OR(N33="",K33=""),"",(N33*60+O33)-(L33*60+M33))
B34: 5. INDICATEURS CALCULÉS | K34: 30 | L34: 15 | M34: 28 | Q34: =IF(OR(N34="",K34=""),"",(N34*60+O34)-(L34*60+M34))
B35: Indicateur | C35: Valeur | D35: Unité | Q35: =IF(OR(N35="",K35=""),"",(N35*60+O35)-(L35*60+M35))
B36: Pièces lancées | C36: =COUNT(K5:K49) -> 30 | D36: pièces | Q36: =IF(OR(N36="",K36=""),"",(N36*60+O36)-(L36*60+M36))
B37: Pièces sorties | C37: =COUNT(Q5:Q49) -> 24 | D37: pièces | Q37: =IF(OR(N37="",K37=""),"",(N37*60+O37)-(L37*60+M37))
B38: Pièces conformes | C38: =COUNTIFS(P5:P49,"O",Q5:Q49,">=0") -> 20 | D38: pièces | Q38: =IF(OR(N38="",K38=""),"",(N38*60+O38)-(L38*60+M38))
B39: Taux de qualité | C39: =IFERROR(C38/C37,"") -> 0.83333333 | Q39: =IF(OR(N39="",K39=""),"",(N39*60+O39)-(L39*60+M39))
B40: WIP (comptage physique) | C40: =C20 -> 6 | D40: pièces | Q40: =IF(OR(N40="",K40=""),"",(N40*60+O40)-(L40*60+M40))
...

Sheet Round 3
A1: ROUND 3 | saisie des relevés
A2: JEU DE DÉMONSTRATION ISSU D'UNE SIMULATION. Effacer toutes les cellules jaunes avant la séance.
B3: 1. TEMPS DE CYCLE PAR POSTE (secondes) | K3: 4. REGISTRE D'EXPÉDITION
B4: Poste | C4: C1 | D4: C2 | E4: C3 | F4: C4 | G4: C5 | H4: Médiane | I4: Écart au takt | K4: Jeton | L4: Entrée (min) | M4: Entrée (s) | N4: Sortie (min) | O4: Sortie (s) | P4: Conforme O/N | Q4: Lead Time (s)
B5: P1 | C5: 19 | D5: 21 | E5: 20 | F5: 21 | G5: 20 | H5: =IF(COUNT(C5:G5)=0,"",MEDIAN(C5:G5)) -> 20 | I5: =IF(H5="","",H5-Paramètres!$C$9) -> -20 | K5: 1 | L5: 0 | M5: 0 | N5: 1 | O5: 41 | P5: O | Q5: =IF(OR(N5="",K5=""),"",(N5*60+O5)-(L5*60+M5)) -> 101
B6: P2 | C6: 26 | D6: 28 | E6: 27 | F6: 28 | G6: 27 | H6: =IF(COUNT(C6:G6)=0,"",MEDIAN(C6:G6)) -> 27 | I6: =IF(H6="","",H6-Paramètres!$C$9) -> -13 | K6: 2 | L6: 0 | M6: 0 | N6: 2 | O6: 15 | P6: O | Q6: =IF(OR(N6="",K6=""),"",(N6*60+O6)-(L6*60+M6)) -> 135
B7: P3 | C7: 27 | D7: 29 | E7: 28 | F7: 29 | G7: 28 | H7: =IF(COUNT(C7:G7)=0,"",MEDIAN(C7:G7)) -> 28 | I7: =IF(H7="","",H7-Paramètres!$C$9) -> -12 | K7: 3 | L7: 0 | M7: 0 | N7: 2 | O7: 44 | P7: O | Q7: =IF(OR(N7="",K7=""),"",(N7*60+O7)-(L7*60+M7)) -> 164
B8: P4 | C8: 26 | D8: 28 | E8: 27 | F8: 28 | G8: 27 | H8: =IF(COUNT(C8:G8)=0,"",MEDIAN(C8:G8)) -> 27 | I8: =IF(H8="","",H8-Paramètres!$C$9) -> -13 | K8: 4 | L8: 0 | M8: 0 | N8: 3 | O8: 15 | P8: O | Q8: =IF(OR(N8="",K8=""),"",(N8*60+O8)-(L8*60+M8)) -> 195
B9: Contenu travail | H9: =IF(COUNT(H5:H8)=0,"",SUM(H5:H8)) -> 102 | K9: 5 | L9: 1 | M9: 41 | N9: 3 | O9: 40 | P9: O | Q9: =IF(OR(N9="",K9=""),"",(N9*60+O9)-(L9*60+M9)) -> 119
B10: Poste goulot (s) | H10: =IF(COUNT(H5:H8)=0,"",MAX(H5:H8)) -> 28 | K10: 6 | L10: 2 | M10: 15 | N10: 4 | O10: 6 | P10: O | Q10: =IF(OR(N10="",K10=""),"",(N10*60+O10)-(L10*60+M10)) -> 111
B11: Écart max entre postes (s) | H11: =IF(COUNT(H5:H8)=0,"",MAX(H5:H8)-MIN(H5:H8)) -> 8 | K11: 7 | L11: 2 | M11: 44 | N11: 4 | O11: 39 | P11: N | Q11: =IF(OR(N11="",K11=""),"",(N11*60+O11)-(L11*60+M11)) -> 115
K12: 8 | L12: 3 | M12: 15 | N12: 5 | O12: 4 | P12: O | Q12: =IF(OR(N12="",K12=""),"",(N12*60+O12)-(L12*60+M12)) -> 109
B13: 2. EN-COURS AU SIGNAL STOP (comptage physique par zone) | K13: 9 | L13: 3 | M13: 40 | N13: 5 | O13: 32 | P13: O | Q13: =IF(OR(N13="",K13=""),"",(N13*60+O13)-(L13*60+M13)) -> 112
B14: Zone | C14: Pièces | K14: 10 | L14: 4 | M14: 6 | N14: 6 | O14: 3 | P14: O | Q14: =IF(OR(N14="",K14=""),"",(N14*60+O14)-(L14*60+M14)) -> 117
B15: Stock matière vers P1 | C15: 0 | K15: 11 | L15: 4 | M15: 39 | N15: 6 | O15: 25 | P15: O | Q15: =IF(OR(N15="",K15=""),"",(N15*60+O15)-(L15*60+M15)) -> 106
B16: P1 vers P2 | C16: 1 | K16: 12 | L16: 5 | M16: 4 | N16: 6 | O16: 51 | P16: O | Q16: =IF(OR(N16="",K16=""),"",(N16*60+O16)-(L16*60+M16)) -> 107
B17: P2 vers P3 | C17: 1 | K17: 13 | L17: 5 | M17: 32 | N17: 7 | O17: 17 | P17: O | Q17: =IF(OR(N17="",K17=""),"",(N17*60+O17)-(L17*60+M17)) -> 105
B18: P3 vers P4 | C18: 1 | K18: 14 | L18: 6 | M18: 3 | N18: 7 | O18: 51 | P18: O | Q18: =IF(OR(N18="",K18=""),"",(N18*60+O18)-(L18*60+M18)) -> 108
B19: P4 vers Client | C19: 1 | K19: 15 | L19: 6 | M19: 25 | N19: 8 | O19: 14 | P19: O | Q19: =IF(OR(N19="",K19=""),"",(N19*60+O19)-(L19*60+M19)) -> 109
B20: WIP TOTAL | C20: =SUM(C15:C19) -> 4 | K20: 16 | L20: 6 | M20: 51 | N20: 8 | O20: 39 | P20: O | Q20: =IF(OR(N20="",K20=""),"",(N20*60+O20)-(L20*60+M20)) -> 108
K21: 17 | L21: 7 | M21: 17 | N21: 9 | O21: 8 | P21: O | Q21: =IF(OR(N21="",K21=""),"",(N21*60+O21)-(L21*60+M21)) -> 111
K22: 18 | L22: 7 | M22: 51 | N22: 9 | O22: 50 | P22: O | Q22: =IF(OR(N22="",K22=""),"",(N22*60+O22)-(L22*60+M22)) -> 119
B23: 3. TABLEAU DE MARCHE | K23: 19 | L23: 8 | M23: 14 | N23: 10 | O23: 15 | P23: O | Q23: =IF(OR(N23="",K23=""),"",(N23*60+O23)-(L23*60+M23)) -> 121
B24: Camion | C24: Heure (min) | D24: Dû | E24: Livré | F24: Retard cumulé | K24: 20 | L24: 8 | M24: 39 | N24: 10 | O24: 49 | P24: O | Q24: =IF(OR(N24="",K24=""),"",(N24*60+O24)-(L24*60+M24)) -> 130
B25: 1 | C25: =(Paramètres!$C$4/Paramètres!$C$7)*1 -> 4 | D25: =Paramètres!$C$8 -> 6 | E25: 5 | F25: =SUM($D$25:D25)-SUM($E$25:E25) -> 1 | K25: 21 | L25: 9 | M25: 8 | N25: 11 | O25: 24 | P25: O | Q25: =IF(OR(N25="",K25=""),"",(N25*60+O25)-(L25*60+M25)) -> 136
B26: 2 | C26: =(Paramètres!$C$4/Paramètres!$C$7)*2 -> 8 | D26: =Paramètres!$C$8 -> 6 | E26: 7 | F26: =SUM($D$25:D26)-SUM($E$25:E26) -> 0 | K26: 22 | L26: 9 | M26: 50 | N26: 11 | O26: 55 | P26: O | Q26: =IF(OR(N26="",K26=""),"",(N26*60+O26)-(L26*60+M26)) -> 125
B27: 3 | C27: =(Paramètres!$C$4/Paramètres!$C$7)*3 -> 12 | D27: =Paramètres!$C$8 -> 6 | E27: 6 | F27: =SUM($D$25:D27)-SUM($E$25:E27) -> 0 | K27: 23 | L27: 10 | M27: 15 | N27: 12 | O27: 20 | P27: O | Q27: =IF(OR(N27="",K27=""),"",(N27*60+O27)-(L27*60+M27)) -> 125
B28: 4 | C28: =(Paramètres!$C$4/Paramètres!$C$7)*4 -> 16 | D28: =Paramètres!$C$8 -> 6 | E28: 6 | F28: =SUM($D$25:D28)-SUM($E$25:E28) -> 0 | K28: 24 | L28: 10 | M28: 49 | N28: 12 | O28: 50 | P28: O | Q28: =IF(OR(N28="",K28=""),"",(N28*60+O28)-(L28*60+M28)) -> 121
B29: Total | D29: =SUM(D25:D28) -> 24 | E29: =SUM(E25:E28) -> 24 | K29: 25 | L29: 11 | M29: 24 | N29: 13 | O29: 17 | P29: O | Q29: =IF(OR(N29="",K29=""),"",(N29*60+O29)-(L29*60+M29)) -> 113
K30: 26 | L30: 11 | M30: 55 | N30: 13 | O30: 48 | P30: N | Q30: =IF(OR(N30="",K30=""),"",(N30*60+O30)-(L30*60+M30)) -> 113
B31: Arrêts de ligne cumulés (s) | C31: 25 | K31: 27 | L31: 12 | M31: 20 | N31: 14 | O31: 15 | P31: O | Q31: =IF(OR(N31="",K31=""),"",(N31*60+O31)-(L31*60+M31)) -> 115
K32: 28 | L32: 12 | M32: 50 | N32: 14 | O32: 43 | P32: O | Q32: =IF(OR(N32="",K32=""),"",(N32*60+O32)-(L32*60+M32)) -> 113
K33: 29 | L33: 13 | M33: 17 | N33: 15 | O33: 11 | P33: O | Q33: =IF(OR(N33="",K33=""),"",(N33*60+O33)-(L33*60+M33)) -> 114
B34: 5. INDICATEURS CALCULÉS | K34: 30 | L34: 13 | M34: 48 | N34: 15 | O34: 41 | P34: O | Q34: =IF(OR(N34="",K34=""),"",(N34*60+O34)-(L34*60+M34)) -> 113
B35: Indicateur | C35: Valeur | D35: Unité | K35: 31 | L35: 14 | M35: 7 | Q35: =IF(OR(N35="",K35=""),"",(N35*60+O35)-(L35*60+M35))
B36: Pièces lancées | C36: =COUNT(K5:K49) -> 34 | D36: pièces | K36: 32 | L36: 14 | M36: 35 | Q36: =IF(OR(N36="",K36=""),"",(N36*60+O36)-(L36*60+M36))
B37: Pièces sorties | C37: =COUNT(Q5:Q49) -> 30 | D37: pièces | K37: 33 | L37: 15 | M37: 4 | Q37: =IF(OR(N37="",K37=""),"",(N37*60+O37)-(L37*60+M37))
B38: Pièces conformes | C38: =COUNTIFS(P5:P49,"O",Q5:Q49,">=0") -> 28 | D38: pièces | K38: 34 | L38: 15 | M38: 32 | Q38: =IF(OR(N38="",K38=""),"",(N38*60+O38)-(L38*60+M38))
B39: Taux de qualité | C39: =IFERROR(C38/C37,"") -> 0.93333333 | Q39: =IF(OR(N39="",K39=""),"",(N39*60+O39)-(L39*60+M39))
B40: WIP (comptage physique) | C40: =C20 -> 4 | D40: pièces | Q40: =IF(OR(N40="",K40=""),"",(N40*60+O40)-(L40*60+M40))
...

Sheet Synthèse
A1: SYNTHÈSE COMPARATIVE ET DÉBRIEFING
B3: 1. TABLEAU COMPARATIF
B4: Indicateur | C4: R1 Poussé | D4: R2 Tiré | E4: R3 Kaizen
B5: Pièces conformes | C5: ='Round 1'!C38 -> 11 | D5: ='Round 2'!C38 -> 20 | E5: ='Round 3'!C38 -> 28
B6: WIP | C6: ='Round 1'!C40 -> 26 | D6: ='Round 2'!C40 -> 6 | E6: ='Round 3'!C40 -> 4
B7: Lead Time moyen (s) | C7: ='Round 1'!C41 -> 605.66667 | D7: ='Round 2'!C41 -> 213 | E7: ='Round 3'!C41 -> 119.66667
B8: Débit (pièces/min) | C8: ='Round 1'!C45 -> 0.9375 | D8: ='Round 2'!C45 -> 1.5 | E8: ='Round 3'!C45 -> 1.875
B9: Temps de cycle ligne (s) | C9: ='Round 1'!C46 -> 64 | D9: ='Round 2'!C46 -> 40 | E9: ='Round 3'!C46 -> 32
B10: Takt Time (s) | C10: =Paramètres!$C$9 -> 40 | D10: =Paramètres!$C$9 -> 40 | E10: =Paramètres!$C$9 -> 40
B11: Contenu travail (s) | C11: ='Round 1'!H9 -> 115 | D11: ='Round 2'!H9 -> 115 | E11: ='Round 3'!H9 -> 102
B12: Ratio d'efficacité | C12: ='Round 1'!C48 -> 0.18987342 | D12: ='Round 2'!C48 -> 0.5399061 | E12: ='Round 3'!C48 -> 0.85236769
B13: Taux de qualité | C13: ='Round 1'!C39 -> 0.73333333 | D13: ='Round 2'!C39 -> 0.83333333 | E13: ='Round 3'!C39 -> 0.93333333
B14: Taux de service client | C14: ='Round 1'!C49 -> 0.45833333 | D14: ='Round 2'!C49 -> 0.83333333 | E14: ='Round 3'!C49 -> 1
B17: 2. TEST DE LA LOI DE LITTLE
B18: WIP = Débit × Lead Time. On compare le Lead Time prédit au Lead Time mesuré.
B19: Grandeur | C19: R1 Poussé | D19: R2 Tiré | E19: R3 Kaizen
B20: WIP mesuré (pièces) | C20: =C6 -> 26 | D20: =D6 -> 6 | E20: =E6 -> 4
B21: Débit mesuré (pièces/min) | C21: =C8 -> 0.9375 | D21: =D8 -> 1.5 | E21: =E8 -> 1.875
B22: Lead Time prédit par Little (s) | C22: =IFERROR(C20/C21*60,"") -> 1664 | D22: =IFERROR(D20/D21*60,"") -> 240 | E22: =IFERROR(E20/E21*60,"") -> 128
B23: Lead Time mesuré (s) | C23: =C7 -> 605.66667 | D23: =D7 -> 213 | E23: =E7 -> 119.66667
B24: Écart relatif | C24: =IFERROR((C22-C23)/C23,"") -> 1.7473858 | D24: =IFERROR((D22-D23)/D23,"") -> 0.12676056 | E24: =IFERROR((E22-E23)/E23,"") -> 0.069637883
B26: La loi de Little suppose un régime permanent, c'est-à-dire un en-cours qui ne dérive pas.
B27: Le CONWIP des rounds 2 et 3 force ce régime : la prédiction tombe juste.
B28: En flux poussé, le WIP grimpe pendant toute la vacation : la prédiction s'effondre.
B29: Conséquence : un atelier en flux poussé est un atelier dont on ne sait pas prédire les délais.
B32: 3. CALCUL DU TRG
B33: TRG = Temps utile / Temps d'ouverture, norme NF E 60-182.
B34: Temps utile = pièces valorisables × temps de cycle de référence. La surproduction n'est pas de la valeur.
B35: Composante | C35: R1 Poussé | D35: R2 Tiré | E35: R3 Kaizen
B36: Pièces sorties | C36: ='Round 1'!C37 -> 15 | D36: ='Round 2'!C37 -> 24 | E36: ='Round 3'!C37 -> 30
B37: Pièces conformes | C37: =C5 -> 11 | D37: =D5 -> 20 | E37: =E5 -> 28
B38: Pièces valorisables = min(conformes ; demande) | C38: =MIN(C37,Paramètres!$C$6) -> 11 | D38: =MIN(D37,Paramètres!$C$6) -> 20 | E38: =MIN(E37,Paramètres!$C$6) -> 24
B39: Temps d'ouverture (s) | C39: =Paramètres!$C$5 -> 960 | D39: =Paramètres!$C$5 -> 960 | E39: =Paramètres!$C$5 -> 960
B40: Arrêts de ligne (s) | C40: ='Round 1'!C31 -> 0 | D40: ='Round 2'!C31 -> 15 | E40: ='Round 3'!C31 -> 25
B41: Temps de fonctionnement (s) | C41: =C39-C40 -> 960 | D41: =D39-D40 -> 945 | E41: =E39-E40 -> 935
B42: Temps utile (s) | C42: =C38*Paramètres!$C$11 -> 385 | D42: =D38*Paramètres!$C$11 -> 700 | E42: =E38*Paramètres!$C$11 -> 840
B43: Disponibilité | C43: =IFERROR(C41/C39,"") -> 1 | D43: =IFERROR(D41/D39,"") -> 0.984375 | E43: =IFERROR(E41/E39,"") -> 0.97395833
B44: Performance | C44: =IFERROR(C36*Paramètres!$C$11/C41,"") -> 0.546875 | D44: =IFERROR(D36*Paramètres!$C$11/D41,"") -> 0.88888889 | E44: =IFERROR(E36*Paramètres!$C$11/E41,"") -> 1.1229947
B45: Taux de valorisation | C45: =IFERROR(C38/C36,"") -> 0.73333333 | D45: =IFERROR(D38/D36,"") -> 0.83333333 | E45: =IFERROR(E38/E36,"") -> 0.8
B46: TRG = D × P × V | C46: =IFERROR(C43*C44*C45,"") -> 0.40104167 | D46: =IFERROR(D43*D44*D45,"") -> 0.72916667 | E46: =IFERROR(E43*E44*E45,"") -> 0.875
...
