Workbook

Sheet Feuille du KRPI
A1: 1 - Définition du pb: QQOQCP | M1: Infos liées à l'intervention
A2: Quoi (Description en 1 phrase) | C2: Quand (date et heure / fréquence) | E2: Où | G2: Qui (op/leader/tech) | I2: Comment (en prod / inter humain) | K2: Pourquoi (qualité/ arret machine / dégradé) | M2: N° DI:/Inter.: 24609 | N2: Programme: ON SEMI NOGENT | O2: Date: 07/01/2025
A3: Vibration portique lors init axe X | C3: 07/01/2025 / à chaque initialisation | E3: Ligne: | F3: A | G3: TLL | I3: En prod | K3: Impossible de lancer en prod | M3: Contact Fournisseurs | O3: ANS
E4: Machine: | F4: Pemtron | M4: -Technicien(s)
E5: N°Corim: | F5: 561,02 | M5: -Mails /Tel | O5: +49604796003
A6: 2 - Recherche des causes possibles : Diagramme d'Ishikawa
B8: Matériel | K8: Matière
B9: Règle incrementale | K9: graisse pas adpaté
B10: tête de lecture
B11: drapeau de home
B12: variateur
B13: // tête lecture <-> règle
B14: moteur / aimant
B15: câble dans dragchain | N15: Pb / effet:
N16: =A3 -> Vibration portique lors init axe X
A18: Préventif non fait | D18: Température de l'atelier | J18: Maintenance mal executé
A19: Gamme pas adapté | J19: Manque de formation
A27: Méthodes | D27: Milieu | J27: Main d'œuvre
A29: 3 - Tri des causes: Est / N'est pas | E29: 4 - Plan d'actions
A31: EST POTENTIELLEMENT | C31: N'EST PAS | E31: Lié à la Cause n° | F31: Action | J31: Resp. | K31: Gain/Effort (Vert= prioritaire beige = modérée ou rouge = non prioritaire) | L31: ordre des OP | M31: Réalisée / Abandon | N31: Amélioration ? Aucun changement /Dégradation du pb / Amelioration du pb/ "Résolution du Pb") | O31: Date, heure & Commentaires
A32: 1 | B32: tête de lecture | C32: moteur / aimant | E32: 1 | F32: Nettoyage tête de lecture | J32: LMS | K32: =Priorité!G3 -> 5 | L32: 1 | M32: Réalisée | N32: Aucun changement | O32: 07/01/25: Règle propre
A33: 2 | B33: câble dans dragchain | C33: drapeau de home
A34: 3 | B34: // tête lect. <-> règle | C34: Règle incrementale | E34: 2 | F34: Vérifier les câbles s'ils ne sont pas pincés | J34: RFS | K34: =Priorité!G4 -> 6 | L34: 5 | M34: Abandon | O34: -
A35: 4 | B35: Température atelier | C35: Variateur
A36: 5 | B36: Maint. Mal executé | E36: 3 | F36: Modifier la position de la tête de lecture | J36: TLL | K36: =Priorité!G5 -> 5 | L36: 2 | M36: Réalisée | N36: Résolution du pb | O36: 07/01/25: Pas de vibration lors init
A37: 6 | B37: Manque de formation
A38: 7 | B38: Preventif non fait | E38: 4 | F38: Vérifier si la température est hors tolérance | J38: TLL | K38: =Priorité!G6 -> 3 | L38: 6 | M38: Abandon
A39: 8 | B39: Gamme pas adapté
A40: 9 | B40: Graisse pas adapté | E40: 7 | F40: Voir si les dernières maintenances préventives ont été bien réalisées | J40: RFS | K40: =Priorité!G7 -> 5 | L40: 3 | M40: Abandon
A41: 10
A42: 11 | E42: 5 & 6 | F42: Verifier si le technicien qui a fait la maintenance preventive est bien formé | J42: RFS | K42: =Priorité!G8 -> 3 | L42: 7 | M42: Abandon
A43: 12
A44: 13 | E44: 8 | F44: Vérifier si fréquence de déclanchement de la gamme est bien adapté | J44: JBM | K44: =Priorité!G9 -> 5 | L44: 4 | M44: Abandon
A45: 14
A46: 4- Suite du Plan d'actions
A48: Lié à la Cause n° | B48: Action | E48: Resp. | F48: Gain/Effort (Vert= prioritaire beige = modérée ou rouge = non prioritaire) | I48: ordre des OP | J48: Réalisée / Abandon | L48: Amélioration ? Aucun changement /Dégradation du pb / Amelioration du pb/ "Résolution du Pb") | N48: Date, heure & Commentaires
A49: 9 | B49: Vérifier si graisse appliquée est bien la bonne | E49: TLL | F49: =Priorité!G10 -> 4 | I49: 8 | J49: Abandon
F51: =Priorité!G11 -> 0
F53: =Priorité!G12 -> 0
F55: =Priorité!G13 -> 0
...

Sheet Priorité
A1: Matrice gain/effort pour définition des priorités Effort : est-ce-qu'on peut le faire de suite ou rapidement + tps intervention Gain: probabilité que le pb vienne de là
A2: Action | C2: Gain (2 ou 4) | E2: Effort (1 ou 2) | G2: Total
A3: ='Feuille du KRPI'!F32 -> Nettoyage tête de lecture | C3: 4 | E3: 1 | G3: =SUM(C3:F3) -> 5
A4: ='Feuille du KRPI'!F34 -> Vérifier les câbles s'ils ne sont pas pincés | C4: 4 | E4: 2 | G4: =SUM(C4:F4) -> 6
A5: ='Feuille du KRPI'!F36 -> Modifier la position de la tête de lecture | C5: 4 | E5: 1 | G5: =SUM(C5:F5) -> 5
A6: ='Feuille du KRPI'!F38 -> Vérifier si la température est hors tolérance | C6: 2 | E6: 1 | G6: =SUM(C6:F6) -> 3
A7: ='Feuille du KRPI'!F40 -> Voir si les dernières maintenances préventives ont été bien réalisées | C7: 4 | E7: 1 | G7: =SUM(C7:F7) -> 5
A8: ='Feuille du KRPI'!F42 -> Verifier si le technicien qui a fait la maintenance preventive est bien formé | C8: 2 | E8: 1 | G8: =SUM(C8:F8) -> 3
A9: ='Feuille du KRPI'!F44 -> Vérifier si fréquence de déclanchement de la gamme est bien adapté | C9: 4 | E9: 1 | G9: =SUM(C9:F9) -> 5
A10: ='Feuille du KRPI'!B49 -> Vérifier si graisse appliquée est bien la bonne | C10: 2 | E10: 2 | G10: =SUM(C10:F10) -> 4
A11: ='Feuille du KRPI'!B51 -> 0 | G11: =SUM(C11:F11) -> 0
A12: ='Feuille du KRPI'!B53 -> 0 | G12: =SUM(C12:F12) -> 0
A13: ='Feuille du KRPI'!B55 -> 0 | G13: =SUM(C13:F13) -> 0
A14: ='Feuille du KRPI'!B57 -> 0 | G14: =SUM(C14:F14) -> 0
A15: ='Feuille du KRPI'!B59 -> 0 | G15: =SUM(C15:F15) -> 0
A16: ='Feuille du KRPI'!B61 -> 0 | G16: =SUM(C16:F16) -> 0
A17: ='Feuille du KRPI'!B63 -> 0 | G17: =SUM(C17:F17) -> 0
A18: ='Feuille du KRPI'!B65 -> 0 | G18: =SUM(C18:F18) -> 0
A19: ='Feuille du KRPI'!B67 -> 0 | G19: =SUM(C19:F19) -> 0
A20: ='Feuille du KRPI'!B69 -> 0 | G20: =SUM(C20:F20) -> 0
A21: ='Feuille du KRPI'!B71 -> 0 | G21: =SUM(C21:F21) -> 0
A22: ='Feuille du KRPI'!B73 -> 0 | G22: =SUM(C22:F22) -> 0
A23: ='Feuille du KRPI'!B75 -> 0 | G23: =SUM(C23:F23) -> 0
A24: ='Feuille du KRPI'!B77 -> 0 | G24: =SUM(C24:F24) -> 0
A25: ='Feuille du KRPI'!B79 -> 0 | G25: =SUM(C25:F25) -> 0
A26: ='Feuille du KRPI'!B81 -> 0 | G26: =SUM(C26:F26) -> 0
A27: ='Feuille du KRPI'!B83 -> 0 | G27: =SUM(C27:F27) -> 0
A28: ='Feuille du KRPI'!B85 -> 0 | G28: =SUM(C28:F28) -> 0
A29: ='Feuille du KRPI'!B87 -> 0 | G29: =SUM(C29:F29) -> 0
A30: ='Feuille du KRPI'!B89 -> 0 | G30: =SUM(C30:F30) -> 0
A31: ='Feuille du KRPI'!B91 -> 0 | G31: =SUM(C31:F31) -> 0

Sheet Principe de fonctionnement
A1: Principe de fonctionnement
A2: Raison déclenchement KRPI : panne de + de 2H sans trouver la root cause
A3: 1) Réunir les techniciens support et un technicien méthode maintenance à la zone de com de l'atelier (Ne pas le remplir à côté de la machine)
A4: 2) Remplir la feuille du KRPI avec les techniciens support
A5: 3) Imprimer la feuille en A3 et la transmettre aux techniciens support
A6: 4) Réaliser les actions en suivant l'ordre de priorité
A7: 5) Compléter la partie commentaire du plan d'action à la main. Le technicien Méthode le renseignera dans le tableau numérique
A8: 6) Lorsque le problème est résolu, il faut rattacher le KRPI avec le compte rendu dans CORIM
A9: Info: Si les techniciens pensent à d'autres actions, ils peuvent les ecrire à la main et le technicien methode le renseignera dans le tableau numérique
A10: Info: Si la panne dure plusieurs 8 ou jours, faire un point d'avancement au changement d'équipe

Sheet liste des champs
A1: Amelioration? | B1: Responsable | C1: Réalisée / Abandon
A2: Aucun changement | B2: AIL | C2: Réalisée
A3: Dégradation du pb | B3: CCS | C3: Abandon
A4: Amelioration du pb | B4: CPT
A5: Résolution du pb | B5: GME
B6: JBM
B7: JBS
B8: LMS
B9: MEE
B10: MPT
B11: NST
B12: Process
B13: RFS
B14: TAA
B15: TDI
B16: Test
B17: TLL
B18: XGO
