Workbook

Sheet Feuille du KRPI
A1: 1 - Définition du pb: QQOQCP | M1: Infos liées à l'intervention
A2: Quoi (Description en 1 phrase) | C2: Quand (date & fréquence) | E2: Où | G2: Qui (op/leader/tech) | I2: Comment (en prod / inter humain) | K2: Pourquoi (qualité/ arret machine / dégradé) | M2: N° DI/Inter. : | N2: Programme: | O2: Date:
E3: Ligne: | M3: Contact Fournisseurs
E4: Machine: | M4: -Technicien(s)
E5: N°Corim: | M5: -Mails /Tel
A6: 2 - Recherche des causes possibles : Diagramme d'Ishikawa
B8: Matériel | K8: Matière
N15: Pb / effet:
N16: =A3 -> 0
A27: Méthodes | D27: Milieu | J27: Main d'œuvre
A29: 3 - Tri des causes: Est / N'est pas | E29: 4 - Plan d'actions
A31: EST POTENTIELLEMENT | C31: N'EST PAS | E31: Lié à la Cause n° | F31: Action | J31: Resp. | K31: Gain/Effort (Vert= prioritaire beige = modérée ou rouge = non prioritaire) | L31: ordre des OP | M31: Réalisée / Abandon | N31: Amélioration ? Aucun changement /Dégradation du pb / Amelioration du pb/ "Résolution du Pb") | O31: Date & Commentaires
A32: 1 | K32: =Priorité!G3 -> 0
A33: 2
A34: 3 | K34: =Priorité!G4 -> 0
A35: 4
A36: 5 | K36: =Priorité!G5 -> 0
A37: 6
A38: 7 | K38: =Priorité!G6 -> 0
A39: 8
A40: 9 | K40: =Priorité!G7 -> 0
A41: 10
A42: 11 | K42: =Priorité!G8 -> 0
A43: 12
A44: 13 | K44: =Priorité!G9 -> 0
A45: 14
A46: 4- Suite du Plan d'actions
A48: Lié à la Cause n° | B48: Action | E48: Resp. | F48: Gain/Effort (Vert= prioritaire beige = modérée ou rouge = non prioritaire) | I48: ordre des OP | J48: Réalisée / Abandon | L48: Amélioration ? Aucun changement /Dégradation du pb / Amelioration du pb/ "Résolution du Pb") | N48: Date, heure & Commentaires
F49: =Priorité!G10 -> 0
F51: =Priorité!G11 -> 0
F53: =Priorité!G12 -> 0
F55: =Priorité!G13 -> 0
F57: =Priorité!G14 -> 0
F59: =Priorité!G15 -> 0
F61: =Priorité!G16 -> 0
F63: =Priorité!G17 -> 0
F65: =Priorité!G18 -> 0
F67: =Priorité!G19 -> 0
F69: =Priorité!G20 -> 0
F71: =Priorité!G21 -> 0
...

Sheet Principe de fonctionnement
A1: Principe de fonctionnement
A2: Raison déclenchement KRPI : panne de + de 2H sans trouver la root cause / Récurrence d'une panne (3x/sem < Panne)
A3: 1) Le technicien support sur le pb remonte l’information au bout de 2H l’info au technicien méthode (Le lancement du KRPI se fait qu’a condition de la présence d’un technicien méthode). Le technicien méthode organise une réunion à la zone de com de l'atelier (Ne pas le remplir à côté de la machine) afin de lancer le KRPI. 2) Remplir le KRPI au format numérique (technicien méthode) avec les techniciens support 3) Imprimer le KRPI en A3 et la transmettre aux techniciens support (technicien méthode) 4) Réaliser les actions en suivant l'ordre de priorité établi (techniciens support) 5) Compléter la partie commentaire du plan d'action(techniciens support) . Le technicien méthode le renseignera dans le tableau numérique ultérieurement Info: Si les techniciens pensent à d'autres actions, ils peuvent les écrire puis le technicien méthode le renseignera dans le tableau numérique 6) Lorsque le problème est résolu, rattacher le KRPI dans le compte rendu CORIM (technicien méthode) 7) Ranger le KRPI dans le dossier KRPI du type de machine (technicien méthode) 8) Renseigner le KRPI dans la liste des KRPI (technicien méthode) Info: Si la panne dure plusieurs 8 ou jours, faire un point d'avancement au changement d'équipe

Sheet Priorité
A1: Matrice gain/effort pour définition des priorités Effort : est-ce-qu'on peut le faire de suite ou rapidement + tps intervention Gain: probabilité que le pb vienne de là
A2: Action | C2: Gain (2 ou 4) | E2: Effort (1 ou 2) | G2: Total
A3: ='Feuille du KRPI'!F32 -> 0 | G3: =SUM(C3:F3) -> 0
A4: ='Feuille du KRPI'!F34 -> 0 | G4: =SUM(C4:F4) -> 0
A5: ='Feuille du KRPI'!F36 -> 0 | G5: =SUM(C5:F5) -> 0
A6: ='Feuille du KRPI'!F38 -> 0 | G6: =SUM(C6:F6) -> 0
A7: ='Feuille du KRPI'!F40 -> 0 | G7: =SUM(C7:F7) -> 0
A8: ='Feuille du KRPI'!F42 -> 0 | G8: =SUM(C8:F8) -> 0
A9: ='Feuille du KRPI'!F44 -> 0 | G9: =SUM(C9:F9) -> 0
A10: ='Feuille du KRPI'!B49 -> 0 | G10: =SUM(C10:F10) -> 0
A11: ='Feuille du KRPI'!B51 -> 0 | G11: =SUM(C11:F11) -> 0
A12: ='Feuille du KRPI'!B53 -> 0 | G12: =SUM(C12:F12) -> 0
A13: ='Feuille du KRPI'!B55 -> 0 | G13: =SUM(C13:F13) -> 0
A14: ='Feuille du KRPI'!B57 -> 0 | G14: =SUM(C14:F14) -> 0
A15: ='Feuille du KRPI'!B59 -> 0 | G15: =SUM(C15:F15) -> 0
A16: ='Feuille du KRPI'!B61 -> 0 | G16: =SUM(C16:F16) -> 0
A17: ='Feuille du KRPI'!B63 -> 0 | G17: =SUM(C17:F17) -> 0
A18: ='Feuille du KRPI'!B65 -> 0 | G18: =SUM(C18:F18) -> 0
A19: ='Feuille du KRPI'!B67 -> 0 | G19: =SUM(C19:F19) -> 0
A20: ='Feuille du KRPI'!B69 -> 0 | G20: =SUM(C20:F20) -> 0
A21: ='Feuille du KRPI'!B71 -> 0 | G21: =SUM(C21:F21) -> 0
A22: ='Feuille du KRPI'!B73 -> 0 | G22: =SUM(C22:F22) -> 0
A23: ='Feuille du KRPI'!B75 -> 0 | G23: =SUM(C23:F23) -> 0
A24: ='Feuille du KRPI'!B77 -> 0 | G24: =SUM(C24:F24) -> 0
A25: ='Feuille du KRPI'!B79 -> 0 | G25: =SUM(C25:F25) -> 0
A26: ='Feuille du KRPI'!B81 -> 0 | G26: =SUM(C26:F26) -> 0
A27: ='Feuille du KRPI'!B83 -> 0 | G27: =SUM(C27:F27) -> 0
A28: ='Feuille du KRPI'!B85 -> 0 | G28: =SUM(C28:F28) -> 0
A29: ='Feuille du KRPI'!B87 -> 0 | G29: =SUM(C29:F29) -> 0
A30: ='Feuille du KRPI'!B89 -> 0 | G30: =SUM(C30:F30) -> 0
A31: ='Feuille du KRPI'!B91 -> 0 | G31: =SUM(C31:F31) -> 0
A32: ='Feuille du KRPI'!B93 -> 0 | G32: =SUM(C32:F32) -> 0

Sheet liste des champs
A1: Amelioration? | B1: Responsable | C1: Réalisée / Abandon
A2: Aucun changement | B2: AIL | C2: Réalisée
A3: Dégradation du pb | B3: CCS | C3: Abandon
A4: Amelioration du pb | B4: CPT
A5: Résolution du pb | B5: GME
B6: JBM
B7: JBS
B8: LMS
B9: MEE
B10: MPT
B11: NST
B12: Process
B13: RFS
B14: TAA
B15: TDI
B16: Test
B17: TLL
B18: XGO
